AttributeError
Python 3.11.4: d:\RPA\template\venv-template\Scripts\python.exe
Tue Sep  5 18:04:40 2023

A problem occurred in a Python script.  Here is the sequence of
function calls leading up to the error, in the order they occurred.

 D:\RPA\template\p000_main.py in <module>
   17     Terminate()
   18 
   19 except Exception as e:
   20 
   21     TerminateAll(e)
TerminateAll = <function TerminateAll>
e undefined

 D:\RPA\template\Assets\Libraries\RPA\control.py in TerminateAll(e=AttributeError("type object 'Settings' has no attribute 'Files'"))
   30     error_html = cgitb.html(sys.exc_info(), context=5)
   31     trace =  "".join(traceback.format_exception(type(e), e, e.__traceback__))
   32     E00_General_Error(error_html, trace)
   33     RPALogging.TerminateLogger(1)
   34     sys.exit(1)  # Stop execution with error result
global E00_General_Error = <class 'Events.e000_general.E00_General_Error'>
error_html = '\n<body bgcolor="#f0f0f8">\n<table width="100%" ce... object \'Settings\' has no attribute \'Files\'\n\n-->\n'
trace = 'Traceback (most recent call last):\n  File "D:\\RP... type object \'Settings\' has no attribute \'Files\'\n'

 D:\RPA\template\Events\e000_general.py in __new__(self=<class 'Events.e000_general.E00_General_Error'>, error_html='\n<body bgcolor="#f0f0f8">\n<table width="100%" ce... object \'Settings\' has no attribute \'Files\'\n\n-->\n', traceback='Traceback (most recent call last):\n  File "D:\\RP... type object \'Settings\' has no attribute \'Files\'\n')
   13         """General Error"""
   14 
   15         self.E01_Send_Error_Report(error_html, traceback)
   16 
   17 
self = <class 'Events.e000_general.E00_General_Error'>
self.E01_Send_Error_Report = <function RPALogging.Task.<locals>.inner>
error_html = '\n<body bgcolor="#f0f0f8">\n<table width="100%" ce... object \'Settings\' has no attribute \'Files\'\n\n-->\n'
traceback = 'Traceback (most recent call last):\n  File "D:\\RP... type object \'Settings\' has no attribute \'Files\'\n'

 D:\RPA\template\Assets\Libraries\RPA\logger.py in inner(*args=('\n<body bgcolor="#f0f0f8">\n<table width="100%" ce... object \'Settings\' has no attribute \'Files\'\n\n-->\n', 'Traceback (most recent call last):\n  File "D:\\RP... type object \'Settings\' has no attribute \'Files\'\n'), **kwargs={})
  139 
  140                         #propaga a exceçao
  141                         raise error
  142                     else:
  143                         #loga a execuçao
error = AttributeError("type object 'Settings' has no attribute 'ErrorEmail'")

 D:\RPA\template\Assets\Libraries\RPA\logger.py in inner(*args=('\n<body bgcolor="#f0f0f8">\n<table width="100%" ce... object \'Settings\' has no attribute \'Files\'\n\n-->\n', 'Traceback (most recent call last):\n  File "D:\\RP... type object \'Settings\' has no attribute \'Files\'\n'), **kwargs={})
   88 
   89                     try:
   90                         f_result = f(*args, **kwargs)     # tenta executar a chamada da funçao
   91                         result = f_result
   92 
f_result undefined
f = <function E00_General_Error.E01_Send_Error_Report>
args = ('\n<body bgcolor="#f0f0f8">\n<table width="100%" ce... object \'Settings\' has no attribute \'Files\'\n\n-->\n', 'Traceback (most recent call last):\n  File "D:\\RP... type object \'Settings\' has no attribute \'Files\'\n')
kwargs = {}

 D:\RPA\template\Events\e000_general.py in E01_Send_Error_Report(error_html='\n<body bgcolor="#f0f0f8">\n<table width="100%" ce... object \'Settings\' has no attribute \'Files\'\n\n-->\n', traceback='Traceback (most recent call last):\n  File "D:\\RP... type object \'Settings\' has no attribute \'Files\'\n')
   30 
   31         SendEmail(
   32             Settings.ErrorEmail['receivers'],
   33             Settings.ErrorEmail['ccs'],
   34             Settings.ErrorEmail['bccs'],
global Settings = <class 'Assets.Libraries.cfg.Settings'>
Settings.ErrorEmail undefined
AttributeError: type object 'Settings' has no attribute 'ErrorEmail'
    __cause__ = None
    __class__ = <class 'AttributeError'>
    __context__ = AttributeError("type object 'Settings' has no attribute 'Files'")
    __delattr__ = <method-wrapper '__delattr__' of AttributeError object>
    __dict__ = {}
    __dir__ = <built-in method __dir__ of AttributeError object>
    __doc__ = 'Attribute not found.'
    __eq__ = <method-wrapper '__eq__' of AttributeError object>
    __format__ = <built-in method __format__ of AttributeError object>
    __ge__ = <method-wrapper '__ge__' of AttributeError object>
    __getattribute__ = <method-wrapper '__getattribute__' of AttributeError object>
    __getstate__ = <built-in method __getstate__ of AttributeError object>
    __gt__ = <method-wrapper '__gt__' of AttributeError object>
    __hash__ = <method-wrapper '__hash__' of AttributeError object>
    __init__ = <method-wrapper '__init__' of AttributeError object>
    __init_subclass__ = <built-in method __init_subclass__ of type object>
    __le__ = <method-wrapper '__le__' of AttributeError object>
    __lt__ = <method-wrapper '__lt__' of AttributeError object>
    __ne__ = <method-wrapper '__ne__' of AttributeError object>
    __new__ = <built-in method __new__ of type object>
    __reduce__ = <built-in method __reduce__ of AttributeError object>
    __reduce_ex__ = <built-in method __reduce_ex__ of AttributeError object>
    __repr__ = <method-wrapper '__repr__' of AttributeError object>
    __setattr__ = <method-wrapper '__setattr__' of AttributeError object>
    __setstate__ = <built-in method __setstate__ of AttributeError object>
    __sizeof__ = <built-in method __sizeof__ of AttributeError object>
    __str__ = <method-wrapper '__str__' of AttributeError object>
    __subclasshook__ = <built-in method __subclasshook__ of type object>
    __suppress_context__ = False
    __traceback__ = <traceback object>
    add_note = <built-in method add_note of AttributeError object>
    args = ("type object 'Settings' has no attribute 'ErrorEmail'",)
    name = 'ErrorEmail'
    obj = <class 'Assets.Libraries.cfg.Settings'>
    with_traceback = <built-in method with_traceback of AttributeError object>

The above is a description of an error in a Python program.  Here is
the original traceback:

Traceback (most recent call last):
  File "D:\RPA\template\p000_main.py", line 15, in <module>
    P003_Write_Issues_To_File(jira_issues)
  File "D:\RPA\template\p003_write_issues_to_file.py", line 12, in __new__
    self.T01_Write_Issues_To_File(issues)
  File "D:\RPA\template\Assets\Libraries\RPA\logger.py", line 141, in inner
    raise error
  File "D:\RPA\template\Assets\Libraries\RPA\logger.py", line 90, in inner
    f_result = f(*args, **kwargs)     # tenta executar a chamada da funçao
               ^^^^^^^^^^^^^^^^^^
  File "D:\RPA\template\p003_write_issues_to_file.py", line 18, in T01_Write_Issues_To_File
    WriteObjectToFile(Settings.Files["jiraIssues"],issues)
                      ^^^^^^^^^^^^^^
AttributeError: type object 'Settings' has no attribute 'Files'

During handling of the above exception, another exception occurred:

Traceback (most recent call last):
  File "D:\RPA\template\p000_main.py", line 21, in <module>
    TerminateAll(e)
  File "D:\RPA\template\Assets\Libraries\RPA\control.py", line 32, in TerminateAll
    E00_General_Error(error_html, trace)
  File "D:\RPA\template\Events\e000_general.py", line 15, in __new__
    self.E01_Send_Error_Report(error_html, traceback)
  File "D:\RPA\template\Assets\Libraries\RPA\logger.py", line 141, in inner
    raise error
  File "D:\RPA\template\Assets\Libraries\RPA\logger.py", line 90, in inner
    f_result = f(*args, **kwargs)     # tenta executar a chamada da funçao
               ^^^^^^^^^^^^^^^^^^
  File "D:\RPA\template\Events\e000_general.py", line 32, in E01_Send_Error_Report
    Settings.ErrorEmail['receivers'],
    ^^^^^^^^^^^^^^^^^^^
AttributeError: type object 'Settings' has no attribute 'ErrorEmail'

