2023-09-05 18:06:07,749 [START] INFO => Process started by diana.s. Args: ['D:\\RPA\\template\\p000_main.py', 'true', 'private_key.pem']

* params: None    
* function duration: None            | * time elapsed: None           
* success:None    
* output: None    


2023-09-05 18:06:07,778 [P001_PROJECT_SETUP] [T01_PROJECT_SETUP]  INFO => Project Setup

* params: []      
* function duration: 0.027228s       | * time elapsed: 1.512365s      
* success: true   
* output: COnfiguração realizda.


2023-09-05 18:07:06,799 [P001_PROJECT_SETUP] [T02_CREATE_JIRA_INSTANCE]  ERROR => None

* params: []      
* function duration: 59.019816s      | * time elapsed: 60.532799s     
* success: false  
* output: Exception
Python 3.11.4: d:\RPA\template\venv-template\Scripts\python.exe
Tue Sep  5 18:07:05 2023

A problem occurred in a Python script.  Here is the sequence of
function calls leading up to the error, in the order they occurred.

 D:\RPA\template\Assets\Libraries\RPA\logger.py in inner(*args=(), **kwargs={})
   90                         f_result = f(*args, **kwargs)     # tenta executar a chamada da funçao
f_result undefined
f = <function P001_Project_Setup.T02_Create_Jira_Instance>
args = ()
kwargs = {}

 D:\RPA\template\p001_project_setup.py in T02_Create_Jira_Instance()
   41         Global.jira : JIRA = CreateJiraInstance(jira_cookies, credential = Credentials.jira)  # Cria uma nova instância do Jira
global Global = <class 'Assets.Libraries.cfg.Global'>
Global.jira undefined
global JIRA = <class 'jira.client.JIRA'>
global CreateJiraInstance = <function CreateJiraInstance>
jira_cookies = [{'domain': 'jira.sidi.org.br', 'httpOnly': False, 'name': 'atlassian.xsrf.token', 'path': '/', 'sameSite': 'Lax', 'secure': True, 'value': 'BOFA-3JJM-HPI5-RE06_3cb19dc55c66d3ee4b649930924bd12356d25462_lout'}, {'domain': 'jira.sidi.org.br', 'httpOnly': True, 'name': 'JSESSIONID', 'path': '/', 'sameSite': 'Lax', 'secure': True, 'value': '4DA49DDABF01FBDB5BDED51F7AB7F501'}, {'domain': 'jira.sidi.org.br', 'httpOnly': False, 'name': 'AzureAppProxyAccessCookie_08cb1455-5466-45eb-aaeb-8e32d6b431de_1.3', 'path': '/', 'sameSite': 'None', 'secure': True, 'value': '4|A257tlIevy27MhIuvFMUMMkhPccFzX1FaVnfrLZOqVjsXd...2ldZdeE1JnmV/pnF63HIHARvQsFhcyUSAc9uFNfyHGwGlL2w='}, {'domain': 'jira.sidi.org.br', 'httpOnly': False, 'name': 'AzureAppProxyAnalyticCookie_08cb1455-5466-45eb-aaeb-8e32d6b431de_https_1.3', 'path': '/', 'sameSite': 'None', 'secure': True, 'value': '4|9NgJjK0MxO4YJ+Yjl9xsqNQ8heExE8HUKXqwhTqSALJAhu...3lKRH7Ib+fgC9Zxn9I8CGMqUloXKbeGC16EoB2gJz8w6A8g=='}, {'domain': 'jira.sidi.org.br', 'expiry': 1693948582, 'httpOnly': False, 'name': 'AzureAppProxyPreauthSessionCookie_08cb1455-5466-...d6b431de_ca82be78-73f0-4c55-8bfe-181cbf86003c_1.4', 'path': '/', 'sameSite': 'None', 'secure': True, 'value': '4|QjodWVPH1kYmTPfeXVdIAJSWaN+l1/IRcoV9nvP82wWKqv...sL6Q317PkNpphUhSvjlXNogxzujSfV/PT7hZyYI+I98E38Q=='}]
credential undefined
global Credentials = <class 'Assets.Libraries.cfg.Credentials'>
Credentials.jira = <Assets.Libraries.RPA.Cryptography.security.Credential object>

 D:\RPA\template\Assets\Libraries\RPA\Cryptography\crypt.py in inner(*args=([{'domain': 'jira.sidi.org.br', 'httpOnly': False, 'name': 'atlassian.xsrf.token', 'path': '/', 'sameSite': 'Lax', 'secure': True, 'value': 'BOFA-3JJM-HPI5-RE06_3cb19dc55c66d3ee4b649930924bd12356d25462_lout'}, {'domain': 'jira.sidi.org.br', 'httpOnly': True, 'name': 'JSESSIONID', 'path': '/', 'sameSite': 'Lax', 'secure': True, 'value': '4DA49DDABF01FBDB5BDED51F7AB7F501'}, {'domain': 'jira.sidi.org.br', 'httpOnly': False, 'name': 'AzureAppProxyAccessCookie_08cb1455-5466-45eb-aaeb-8e32d6b431de_1.3', 'path': '/', 'sameSite': 'None', 'secure': True, 'value': '4|A257tlIevy27MhIuvFMUMMkhPccFzX1FaVnfrLZOqVjsXd...2ldZdeE1JnmV/pnF63HIHARvQsFhcyUSAc9uFNfyHGwGlL2w='}, {'domain': 'jira.sidi.org.br', 'httpOnly': False, 'name': 'AzureAppProxyAnalyticCookie_08cb1455-5466-45eb-aaeb-8e32d6b431de_https_1.3', 'path': '/', 'sameSite': 'None', 'secure': True, 'value': '4|9NgJjK0MxO4YJ+Yjl9xsqNQ8heExE8HUKXqwhTqSALJAhu...3lKRH7Ib+fgC9Zxn9I8CGMqUloXKbeGC16EoB2gJz8w6A8g=='}, {'domain': 'jira.sidi.org.br', 'expiry': 1693948582, 'httpOnly': False, 'name': 'AzureAppProxyPreauthSessionCookie_08cb1455-5466-...d6b431de_ca82be78-73f0-4c55-8bfe-181cbf86003c_1.4', 'path': '/', 'sameSite': 'None', 'secure': True, 'value': '4|QjodWVPH1kYmTPfeXVdIAJSWaN+l1/IRcoV9nvP82wWKqv...sL6Q317PkNpphUhSvjlXNogxzujSfV/PT7hZyYI+I98E38Q=='}],), **kwargs={'credential': <Assets.Libraries.RPA.Cryptography.security.Credential object>, 'decrypted_credential': <Assets.Libraries.RPA.Cryptography.security.Credential object>})
   84                     raise Exception(f"Houve um erro na chamada da função {str(f.__qualname__.split('.')[0]).upper()}.")
builtinException = <class 'Exception'>
Exception: Houve um erro na chamada da função CREATEJIRAINSTANCE.
    __cause__ = None
    __class__ = <class 'Exception'>
    __context__ = JSONDecodeError('Expecting value: line 3 column 1 (char 4)')
    __delattr__ = <method-wrapper '__delattr__' of Exception object>
    __dict__ = {}
    __dir__ = <built-in method __dir__ of Exception object>
    __doc__ = 'Common base class for all non-exit exceptions.'
    __eq__ = <method-wrapper '__eq__' of Exception object>
    __format__ = <built-in method __format__ of Exception object>
    __ge__ = <method-wrapper '__ge__' of Exception object>
    __getattribute__ = <method-wrapper '__getattribute__' of Exception object>
    __getstate__ = <built-in method __getstate__ of Exception object>
    __gt__ = <method-wrapper '__gt__' of Exception object>
    __hash__ = <method-wrapper '__hash__' of Exception object>
    __init__ = <method-wrapper '__init__' of Exception object>
    __init_subclass__ = <built-in method __init_subclass__ of type object>
    __le__ = <method-wrapper '__le__' of Exception object>
    __lt__ = <method-wrapper '__lt__' of Exception object>
    __ne__ = <method-wrapper '__ne__' of Exception object>
    __new__ = <built-in method __new__ of type object>
    __reduce__ = <built-in method __reduce__ of Exception object>
    __reduce_ex__ = <built-in method __reduce_ex__ of Exception object>
    __repr__ = <method-wrapper '__repr__' of Exception object>
    __setattr__ = <method-wrapper '__setattr__' of Exception object>
    __setstate__ = <built-in method __setstate__ of Exception object>
    __sizeof__ = <built-in method __sizeof__ of Exception object>
    __str__ = <method-wrapper '__str__' of Exception object>
    __subclasshook__ = <built-in method __subclasshook__ of type object>
    __suppress_context__ = False
    __traceback__ = <traceback object>
    add_note = <built-in method add_note of Exception object>
    args = ('Houve um erro na chamada da função CREATEJIRAINSTANCE.',)
    with_traceback = <built-in method with_traceback of Exception object>

The above is a description of an error in a Python program.  Here is
the original traceback:

Traceback (most recent call last):
  File "d:\RPA\template\venv-template\Lib\site-packages\requests\models.py", line 971, in json
    return complexjson.loads(self.text, **kwargs)
           ^^^^^^^^^^^^^^^^^^^^^^^^^^^^^^^^^^^^^^
  File "C:\Python311\Lib\json\__init__.py", line 346, in loads
    return _default_decoder.decode(s)
           ^^^^^^^^^^^^^^^^^^^^^^^^^^
  File "C:\Python311\Lib\json\decoder.py", line 337, in decode
    obj, end = self.raw_decode(s, idx=_w(s, 0).end())
               ^^^^^^^^^^^^^^^^^^^^^^^^^^^^^^^^^^^^^^
  File "C:\Python311\Lib\json\decoder.py", line 355, in raw_decode
    raise JSONDecodeError("Expecting value", s, err.value) from None
json.decoder.JSONDecodeError: Expecting value: line 3 column 1 (char 4)

During handling of the above exception, another exception occurred:

Traceback (most recent call last):
  File "D:\RPA\template\Assets\Libraries\RPA\Cryptography\crypt.py", line 60, in inner
    result = f(*args, **kwargs) # Chama a função, passando seus argumentos originais (que já contém a credencial criptografada)
             ^^^^^^^^^^^^^^^^^^
  File "D:\RPA\template\Assets\Libraries\Auth\session.py", line 38, in CreateJiraInstance
    return JIRA(
           ^^^^^
  File "d:\RPA\template\venv-template\Lib\site-packages\jira\client.py", line 580, in __init__
    si = self.server_info()
         ^^^^^^^^^^^^^^^^^^
  File "d:\RPA\template\venv-template\Lib\site-packages\jira\client.py", line 3120, in server_info
    j = self._get_json("serverInfo")
        ^^^^^^^^^^^^^^^^^^^^^^^^^^^^
  File "d:\RPA\template\venv-template\Lib\site-packages\jira\client.py", line 3858, in _get_json
    raise e
  File "d:\RPA\template\venv-template\Lib\site-packages\jira\client.py", line 3855, in _get_json
    r_json = json_loads(r)
             ^^^^^^^^^^^^^
  File "d:\RPA\template\venv-template\Lib\site-packages\jira\utils\__init__.py", line 76, in json_loads
    return resp.json()
           ^^^^^^^^^^^
  File "d:\RPA\template\venv-template\Lib\site-packages\requests\models.py", line 975, in json
    raise RequestsJSONDecodeError(e.msg, e.doc, e.pos)
requests.exceptions.JSONDecodeError: Expecting value: line 3 column 1 (char 4)

During handling of the above exception, another exception occurred:

Traceback (most recent call last):
  File "D:\RPA\template\Assets\Libraries\RPA\logger.py", line 90, in inner
    f_result = f(*args, **kwargs)     # tenta executar a chamada da funçao
               ^^^^^^^^^^^^^^^^^^
  File "D:\RPA\template\p001_project_setup.py", line 41, in T02_Create_Jira_Instance
    Global.jira : JIRA = CreateJiraInstance(jira_cookies, credential = Credentials.jira)  # Cria uma nova instância do Jira
                       ^^^^^^^^^^^^^^^^^^^^^^^^^^^^^^^^^^^^^^^^^^^^^^^^^^^^^^^^^^^^^^^
  File "D:\RPA\template\Assets\Libraries\RPA\Cryptography\crypt.py", line 84, in inner
    raise Exception(f"Houve um erro na chamada da função {str(f.__qualname__.split('.')[0]).upper()}.")
Exception: Houve um erro na chamada da função CREATEJIRAINSTANCE.



NoneType: None
2023-09-05 18:07:07,647 [E00_GENERAL_ERROR] [E01_SEND_ERROR_REPORT]  ERROR => Send error e-mail

* params: ['\n<body bgcolor="#f0f0f8">\n<table width="100%" cellspacing=0 cellpadding=2 border=0 summary="heading">\n<tr bgcolor="#6622aa">\n<td valign=bottom>&nbsp;<br>\n<font color="#ffffff" face="helvetica, arial">&nbsp;<br>\n<big><big><strong>Exception</strong></big></big></font></td>\n<td align=right valign=bottom>\n<font color="#ffffff" face="helvetica, arial">Python 3.11.4: d:\\RPA\\template\\venv-template\\Scripts\\python.exe<br>Tue Sep  5 18:07:06 2023</font></td>\n</tr></table>\n<p>A problem occurred in a Python script.  Here is the sequence of\nfunction calls leading up to the error, in the order they occurred.</p>\n<table width="100%" cellspacing=0 cellpadding=0 border=0>\n<tr><td bgcolor="#d8bbff"><big>&nbsp;</big><a href="file://D:\\RPA\\template\\p000_main.py">D:\\RPA\\template\\p000_main.py</a> in <strong>&lt;module&gt;</strong></td></tr>\n<tr><td><font color="#909090"><tt>&nbsp;&nbsp;<small>&nbsp;&nbsp;&nbsp;&nbsp;9</small>&nbsp;try:<br>\n</tt></font></td></tr>\n<tr><td><font color="#909090"><tt>&nbsp;&nbsp;<small>&nbsp;&nbsp;&nbsp;10</small>&nbsp;<br>\n</tt></font></td></tr>\n<tr><td bgcolor="#ffccee"><tt>=&gt;<small>&nbsp;&nbsp;&nbsp;11</small>&nbsp;&nbsp;&nbsp;&nbsp;&nbsp;P001_Project_Setup()<br>\n</tt></td></tr>\n<tr><td><font color="#909090"><tt>&nbsp;&nbsp;<small>&nbsp;&nbsp;&nbsp;12</small>&nbsp;&nbsp;&nbsp;&nbsp;&nbsp;<br>\n</tt></font></td></tr>\n<tr><td><font color="#909090"><tt>&nbsp;&nbsp;<small>&nbsp;&nbsp;&nbsp;13</small>&nbsp;&nbsp;&nbsp;&nbsp;&nbsp;jira_issues&nbsp;=&nbsp;P002_Get_Jira_Issues()<br>\n</tt></font></td></tr>\n<tr><td><small><font color="#909090"><strong>P001_Project_Setup</strong>&nbsp;= &lt;class \'p001_project_setup.P001_Project_Setup\'&gt;</font></small></td></tr></table>\n<table width="100%" cellspacing=0 cellpadding=0 border=0>\n<tr><td bgcolor="#d8bbff"><big>&nbsp;</big><a href="file://D:\\RPA\\template\\p001_project_setup.py">D:\\RPA\\template\\p001_project_setup.py</a> in <strong>__new__</strong>(self=&lt;class \'p001_project_setup.P001_Project_Setup\'&gt;)</td></tr>\n<tr><td><font color="#909090"><tt>&nbsp;&nbsp;<small>&nbsp;&nbsp;&nbsp;18</small>&nbsp;&nbsp;&nbsp;&nbsp;&nbsp;&nbsp;&nbsp;&nbsp;&nbsp;<br>\n</tt></font></td></tr>\n<tr><td><font color="#909090"><tt>&nbsp;&nbsp;<small>&nbsp;&nbsp;&nbsp;19</small>&nbsp;&nbsp;&nbsp;&nbsp;&nbsp;&nbsp;&nbsp;&nbsp;&nbsp;self.T01_Project_Setup()<br>\n</tt></font></td></tr>\n<tr><td bgcolor="#ffccee"><tt>=&gt;<small>&nbsp;&nbsp;&nbsp;20</small>&nbsp;&nbsp;&nbsp;&nbsp;&nbsp;&nbsp;&nbsp;&nbsp;&nbsp;self.T02_Create_Jira_Instance()<br>\n</tt></td></tr>\n<tr><td><font color="#909090"><tt>&nbsp;&nbsp;<small>&nbsp;&nbsp;&nbsp;21</small>&nbsp;<br>\n</tt></font></td></tr>\n<tr><td><font color="#909090"><tt>&nbsp;&nbsp;<small>&nbsp;&nbsp;&nbsp;22</small>&nbsp;&nbsp;&nbsp;&nbsp;&nbsp;def&nbsp;T01_Project_Setup():<br>\n</tt></font></td></tr>\n<tr><td><small><font color="#909090"><strong>self</strong>&nbsp;= &lt;class \'p001_project_setup.P001_Project_Setup\'&gt;, self.<strong>T02_Create_Jira_Instance</strong>&nbsp;= &lt;function RPALogging.Task.&lt;locals&gt;.inner&gt;</font></small></td></tr></table>\n<table width="100%" cellspacing=0 cellpadding=0 border=0>\n<tr><td bgcolor="#d8bbff"><big>&nbsp;</big><a href="file://D:\\RPA\\template\\Assets\\Libraries\\RPA\\logger.py">D:\\RPA\\template\\Assets\\Libraries\\RPA\\logger.py</a> in <strong>inner</strong>(*args=(), **kwargs={})</td></tr>\n<tr><td><font color="#909090"><tt>&nbsp;&nbsp;<small>&nbsp;&nbsp;139</small>&nbsp;&nbsp;&nbsp;&nbsp;&nbsp;&nbsp;&nbsp;&nbsp;&nbsp;&nbsp;&nbsp;&nbsp;&nbsp;&nbsp;&nbsp;&nbsp;&nbsp;&nbsp;&nbsp;&nbsp;&nbsp;&nbsp;&nbsp;&nbsp;&nbsp;<br>\n</tt></font></td></tr>\n<tr><td><font color="#909090"><tt>&nbsp;&nbsp;<small>&nbsp;&nbsp;140</small>&nbsp;&nbsp;&nbsp;&nbsp;&nbsp;&nbsp;&nbsp;&nbsp;&nbsp;&nbsp;&nbsp;&nbsp;&nbsp;&nbsp;&nbsp;&nbsp;&nbsp;&nbsp;&nbsp;&nbsp;&nbsp;&nbsp;&nbsp;&nbsp;&nbsp;#propaga&nbsp;a&nbsp;exceçao<br>\n</tt></font></td></tr>\n<tr><td bgcolor="#ffccee"><tt>=&gt;<small>&nbsp;&nbsp;141</small>&nbsp;&nbsp;&nbsp;&nbsp;&nbsp;&nbsp;&nbsp;&nbsp;&nbsp;&nbsp;&nbsp;&nbsp;&nbsp;&nbsp;&nbsp;&nbsp;&nbsp;&nbsp;&nbsp;&nbsp;&nbsp;&nbsp;&nbsp;&nbsp;&nbsp;raise&nbsp;error&nbsp;<br>\n</tt></td></tr>\n<tr><td><font color="#909090"><tt>&nbsp;&nbsp;<small>&nbsp;&nbsp;142</small>&nbsp;&nbsp;&nbsp;&nbsp;&nbsp;&nbsp;&nbsp;&nbsp;&nbsp;&nbsp;&nbsp;&nbsp;&nbsp;&nbsp;&nbsp;&nbsp;&nbsp;&nbsp;&nbsp;&nbsp;&nbsp;else:<br>\n</tt></font></td></tr>\n<tr><td><font color="#909090"><tt>&nbsp;&nbsp;<small>&nbsp;&nbsp;143</small>&nbsp;&nbsp;&nbsp;&nbsp;&nbsp;&nbsp;&nbsp;&nbsp;&nbsp;&nbsp;&nbsp;&nbsp;&nbsp;&nbsp;&nbsp;&nbsp;&nbsp;&nbsp;&nbsp;&nbsp;&nbsp;&nbsp;&nbsp;&nbsp;&nbsp;#loga&nbsp;a&nbsp;execuçao<br>\n</tt></font></td></tr>\n<tr><td><small><font color="#909090"><strong>error</strong>&nbsp;= Exception(\'Houve um erro na chamada da função CREATEJIRAINSTANCE.\')</font></small></td></tr></table>\n<table width="100%" cellspacing=0 cellpadding=0 border=0>\n<tr><td bgcolor="#d8bbff"><big>&nbsp;</big><a href="file://D:\\RPA\\template\\Assets\\Libraries\\RPA\\logger.py">D:\\RPA\\template\\Assets\\Libraries\\RPA\\logger.py</a> in <strong>inner</strong>(*args=(), **kwargs={})</td></tr>\n<tr><td><font color="#909090"><tt>&nbsp;&nbsp;<small>&nbsp;&nbsp;&nbsp;88</small>&nbsp;<br>\n</tt></font></td></tr>\n<tr><td><font color="#909090"><tt>&nbsp;&nbsp;<small>&nbsp;&nbsp;&nbsp;89</small>&nbsp;&nbsp;&nbsp;&nbsp;&nbsp;&nbsp;&nbsp;&nbsp;&nbsp;&nbsp;&nbsp;&nbsp;&nbsp;&nbsp;&nbsp;&nbsp;&nbsp;&nbsp;&nbsp;&nbsp;&nbsp;try:<br>\n</tt></font></td></tr>\n<tr><td bgcolor="#ffccee"><tt>=&gt;<small>&nbsp;&nbsp;&nbsp;90</small>&nbsp;&nbsp;&nbsp;&nbsp;&nbsp;&nbsp;&nbsp;&nbsp;&nbsp;&nbsp;&nbsp;&nbsp;&nbsp;&nbsp;&nbsp;&nbsp;&nbsp;&nbsp;&nbsp;&nbsp;&nbsp;&nbsp;&nbsp;&nbsp;&nbsp;f_result&nbsp;=&nbsp;f(*args,&nbsp;**kwargs)&nbsp;&nbsp;&nbsp;&nbsp;&nbsp;#&nbsp;tenta&nbsp;executar&nbsp;a&nbsp;chamada&nbsp;da&nbsp;funçao<br>\n</tt></td></tr>\n<tr><td><font color="#909090"><tt>&nbsp;&nbsp;<small>&nbsp;&nbsp;&nbsp;91</small>&nbsp;&nbsp;&nbsp;&nbsp;&nbsp;&nbsp;&nbsp;&nbsp;&nbsp;&nbsp;&nbsp;&nbsp;&nbsp;&nbsp;&nbsp;&nbsp;&nbsp;&nbsp;&nbsp;&nbsp;&nbsp;&nbsp;&nbsp;&nbsp;&nbsp;result&nbsp;=&nbsp;f_result<br>\n</tt></font></td></tr>\n<tr><td><font color="#909090"><tt>&nbsp;&nbsp;<small>&nbsp;&nbsp;&nbsp;92</small>&nbsp;&nbsp;&nbsp;&nbsp;&nbsp;&nbsp;&nbsp;&nbsp;&nbsp;&nbsp;&nbsp;&nbsp;&nbsp;&nbsp;&nbsp;&nbsp;&nbsp;&nbsp;&nbsp;&nbsp;&nbsp;&nbsp;&nbsp;&nbsp;&nbsp;<br>\n</tt></font></td></tr>\n<tr><td><small><font color="#909090">f_result <em>undefined</em>, <strong>f</strong>&nbsp;= &lt;function P001_Project_Setup.T02_Create_Jira_Instance&gt;, <strong>args</strong>&nbsp;= (), <strong>kwargs</strong>&nbsp;= {}</font></small></td></tr></table>\n<table width="100%" cellspacing=0 cellpadding=0 border=0>\n<tr><td bgcolor="#d8bbff"><big>&nbsp;</big><a href="file://D:\\RPA\\template\\p001_project_setup.py">D:\\RPA\\template\\p001_project_setup.py</a> in <strong>T02_Create_Jira_Instance</strong>()</td></tr>\n<tr><td><font color="#909090"><tt>&nbsp;&nbsp;<small>&nbsp;&nbsp;&nbsp;39</small>&nbsp;<br>\n</tt></font></td></tr>\n<tr><td><font color="#909090"><tt>&nbsp;&nbsp;<small>&nbsp;&nbsp;&nbsp;40</small>&nbsp;&nbsp;&nbsp;&nbsp;&nbsp;&nbsp;&nbsp;&nbsp;&nbsp;#&nbsp;Inicie&nbsp;uma&nbsp;sessão&nbsp;http&nbsp;autenticada&nbsp;com&nbsp;a&nbsp;API&nbsp;do&nbsp;Jira&nbsp;usando&nbsp;os&nbsp;parâmetros&nbsp;e&nbsp;cookies&nbsp;fornecidos.<br>\n</tt></font></td></tr>\n<tr><td bgcolor="#ffccee"><tt>=&gt;<small>&nbsp;&nbsp;&nbsp;41</small>&nbsp;&nbsp;&nbsp;&nbsp;&nbsp;&nbsp;&nbsp;&nbsp;&nbsp;Global.jira&nbsp;:&nbsp;JIRA&nbsp;=&nbsp;CreateJiraInstance(jira_cookies,&nbsp;credential&nbsp;=&nbsp;Credentials.jira)&nbsp;&nbsp;#&nbsp;Cria&nbsp;uma&nbsp;nova&nbsp;instância&nbsp;do&nbsp;Jira&nbsp;&nbsp;<br>\n</tt></td></tr>\n<tr><td><font color="#909090"><tt>&nbsp;&nbsp;<small>&nbsp;&nbsp;&nbsp;42</small>&nbsp;&nbsp;&nbsp;&nbsp;&nbsp;&nbsp;&nbsp;&nbsp;&nbsp;<br>\n</tt></font></td></tr>\n<tr><td><font color="#909090"><tt>&nbsp;&nbsp;<small>&nbsp;&nbsp;&nbsp;43</small>&nbsp;&nbsp;&nbsp;&nbsp;&nbsp;&nbsp;&nbsp;&nbsp;&nbsp;return&nbsp', 'Traceback (most recent call last):\n  File "d:\\RPA\\template\\venv-template\\Lib\\site-packages\\requests\\models.py", line 971, in json\n    return complexjson.loads(self.text, **kwargs)\n           ^^^^^^^^^^^^^^^^^^^^^^^^^^^^^^^^^^^^^^\n  File "C:\\Python311\\Lib\\json\\__init__.py", line 346, in loads\n    return _default_decoder.decode(s)\n           ^^^^^^^^^^^^^^^^^^^^^^^^^^\n  File "C:\\Python311\\Lib\\json\\decoder.py", line 337, in decode\n    obj, end = self.raw_decode(s, idx=_w(s, 0).end())\n               ^^^^^^^^^^^^^^^^^^^^^^^^^^^^^^^^^^^^^^\n  File "C:\\Python311\\Lib\\json\\decoder.py", line 355, in raw_decode\n    raise JSONDecodeError("Expecting value", s, err.value) from None\njson.decoder.JSONDecodeError: Expecting value: line 3 column 1 (char 4)\n\nDuring handling of the above exception, another exception occurred:\n\nTraceback (most recent call last):\n  File "D:\\RPA\\template\\Assets\\Libraries\\RPA\\Cryptography\\crypt.py", line 60, in inner\n    result = f(*args, **kwargs) # Chama a função, passando seus argumentos originais (que já contém a credencial criptografada)\n             ^^^^^^^^^^^^^^^^^^\n  File "D:\\RPA\\template\\Assets\\Libraries\\Auth\\session.py", line 38, in CreateJiraInstance\n    return JIRA(\n           ^^^^^\n  File "d:\\RPA\\template\\venv-template\\Lib\\site-packages\\jira\\client.py", line 580, in __init__\n    si = self.server_info()\n         ^^^^^^^^^^^^^^^^^^\n  File "d:\\RPA\\template\\venv-template\\Lib\\site-packages\\jira\\client.py", line 3120, in server_info\n    j = self._get_json("serverInfo")\n        ^^^^^^^^^^^^^^^^^^^^^^^^^^^^\n  File "d:\\RPA\\template\\venv-template\\Lib\\site-packages\\jira\\client.py", line 3858, in _get_json\n    raise e\n  File "d:\\RPA\\template\\venv-template\\Lib\\site-packages\\jira\\client.py", line 3855, in _get_json\n    r_json = json_loads(r)\n             ^^^^^^^^^^^^^\n  File "d:\\RPA\\template\\venv-template\\Lib\\site-packages\\jira\\utils\\__init__.py", line 76, in json_loads\n    return resp.json()\n           ^^^^^^^^^^^\n  File "d:\\RPA\\template\\venv-template\\Lib\\site-packages\\requests\\models.py", line 975, in json\n    raise RequestsJSONDecodeError(e.msg, e.doc, e.pos)\nrequests.exceptions.JSONDecodeError: Expecting value: line 3 column 1 (char 4)\n\nDuring handling of the above exception, another exception occurred:\n\nTraceback (most recent call last):\n  File "D:\\RPA\\template\\p000_main.py", line 11, in <module>\n    P001_Project_Setup()\n  File "D:\\RPA\\template\\p001_project_setup.py", line 20, in __new__\n    self.T02_Create_Jira_Instance()\n  File "D:\\RPA\\template\\Assets\\Libraries\\RPA\\logger.py", line 141, in inner\n    raise error\n  File "D:\\RPA\\template\\Assets\\Libraries\\RPA\\logger.py", line 90, in inner\n    f_result = f(*args, **kwargs)     # tenta executar a chamada da funçao\n               ^^^^^^^^^^^^^^^^^^\n  File "D:\\RPA\\template\\p001_project_setup.py", line 41, in T02_Create_Jira_Instance\n    Global.jira : JIRA = CreateJiraInstance(jira_cookies, credential = Credentials.jira)  # Cria uma nova instância do Jira\n                       ^^^^^^^^^^^^^^^^^^^^^^^^^^^^^^^^^^^^^^^^^^^^^^^^^^^^^^^^^^^^^^^\n  File "D:\\RPA\\template\\Assets\\Libraries\\RPA\\Cryptography\\crypt.py", line 84, in inner\n    raise Exception(f"Houve um erro na chamada da função {str(f.__qualname__.split(\'.\')[0]).upper()}.")\nException: Houve um erro na chamada da função CREATEJIRAINSTANCE.\n']
* function duration: 0.830155s       | * time elapsed: 61.381598s     
* success: false  
* output: Exception
Python 3.11.4: d:\RPA\template\venv-template\Scripts\python.exe
Tue Sep  5 18:07:07 2023

A problem occurred in a Python script.  Here is the sequence of
function calls leading up to the error, in the order they occurred.

 D:\RPA\template\Assets\Libraries\RPA\logger.py in inner(*args=('\n<body bgcolor="#f0f0f8">\n<table width="100%" ce...ro na chamada da função CREATEJIRAINSTANCE.\n\n-->\n', 'Traceback (most recent call last):\n  File "d:\\RP...um erro na chamada da função CREATEJIRAINSTANCE.\n'), **kwargs={})
   90                         f_result = f(*args, **kwargs)     # tenta executar a chamada da funçao
f_result undefined
f = <function E00_General_Error.E01_Send_Error_Report>
args = ('\n<body bgcolor="#f0f0f8">\n<table width="100%" ce...ro na chamada da função CREATEJIRAINSTANCE.\n\n-->\n', 'Traceback (most recent call last):\n  File "d:\\RP...um erro na chamada da função CREATEJIRAINSTANCE.\n')
kwargs = {}

 D:\RPA\template\Events\e000_general.py in E01_Send_Error_Report(error_html='\n<body bgcolor="#f0f0f8">\n<table width="100%" ce...ro na chamada da função CREATEJIRAINSTANCE.\n\n-->\n', traceback='Traceback (most recent call last):\n  File "d:\\RP...um erro na chamada da função CREATEJIRAINSTANCE.\n')
   31         SendEmail(
global SendEmail = <function SendEmail>
global Settings = <class 'Assets.Libraries.cfg.Settings'>
Settings.error_email = {'bccs': ['rpa.bot@sidi.org.br'], 'ccs': ['s.aguena@sidi.org.br'], 'receivers': ['diana.s@sidi.org.br'], 'subject': '[RPA Error] Template V7.0'}
body = '\n<body bgcolor="#f0f0f8">\n<table width="100%" ce...ro na chamada da função CREATEJIRAINSTANCE.\n\n-->\n'
log_zip_path = r'History\2023\09\05\log.zip'
credential undefined
global Credentials = <class 'Assets.Libraries.cfg.Credentials'>
Credentials.microsoft = <Assets.Libraries.RPA.Cryptography.security.Credential object>

 D:\RPA\template\Assets\Libraries\RPA\Cryptography\crypt.py in inner(*args=(['diana.s@sidi.org.br'], ['s.aguena@sidi.org.br'], ['rpa.bot@sidi.org.br'], '[RPA Error] Template V7.0', '\n<body bgcolor="#f0f0f8">\n<table width="100%" ce...ro na chamada da função CREATEJIRAINSTANCE.\n\n-->\n', [r'History\2023\09\05\log.zip']), **kwargs={'credential': <Assets.Libraries.RPA.Cryptography.security.Credential object>, 'decrypted_credential': <Assets.Libraries.RPA.Cryptography.security.Credential object>})
   84                     raise Exception(f"Houve um erro na chamada da função {str(f.__qualname__.split('.')[0]).upper()}.")
builtinException = <class 'Exception'>
Exception: Houve um erro na chamada da função SENDEMAIL.
    __cause__ = None
    __class__ = <class 'Exception'>
    __context__ = AttributeError("type object 'Global' has no attribute 'Email'")
    __delattr__ = <method-wrapper '__delattr__' of Exception object>
    __dict__ = {}
    __dir__ = <built-in method __dir__ of Exception object>
    __doc__ = 'Common base class for all non-exit exceptions.'
    __eq__ = <method-wrapper '__eq__' of Exception object>
    __format__ = <built-in method __format__ of Exception object>
    __ge__ = <method-wrapper '__ge__' of Exception object>
    __getattribute__ = <method-wrapper '__getattribute__' of Exception object>
    __getstate__ = <built-in method __getstate__ of Exception object>
    __gt__ = <method-wrapper '__gt__' of Exception object>
    __hash__ = <method-wrapper '__hash__' of Exception object>
    __init__ = <method-wrapper '__init__' of Exception object>
    __init_subclass__ = <built-in method __init_subclass__ of type object>
    __le__ = <method-wrapper '__le__' of Exception object>
    __lt__ = <method-wrapper '__lt__' of Exception object>
    __ne__ = <method-wrapper '__ne__' of Exception object>
    __new__ = <built-in method __new__ of type object>
    __reduce__ = <built-in method __reduce__ of Exception object>
    __reduce_ex__ = <built-in method __reduce_ex__ of Exception object>
    __repr__ = <method-wrapper '__repr__' of Exception object>
    __setattr__ = <method-wrapper '__setattr__' of Exception object>
    __setstate__ = <built-in method __setstate__ of Exception object>
    __sizeof__ = <built-in method __sizeof__ of Exception object>
    __str__ = <method-wrapper '__str__' of Exception object>
    __subclasshook__ = <built-in method __subclasshook__ of type object>
    __suppress_context__ = False
    __traceback__ = <traceback object>
    add_note = <built-in method add_note of Exception object>
    args = ('Houve um erro na chamada da função SENDEMAIL.',)
    with_traceback = <built-in method with_traceback of Exception object>

The above is a description of an error in a Python program.  Here is
the original traceback:

Traceback (most recent call last):
  File "d:\RPA\template\venv-template\Lib\site-packages\requests\models.py", line 971, in json
    return complexjson.loads(self.text, **kwargs)
           ^^^^^^^^^^^^^^^^^^^^^^^^^^^^^^^^^^^^^^
  File "C:\Python311\Lib\json\__init__.py", line 346, in loads
    return _default_decoder.decode(s)
           ^^^^^^^^^^^^^^^^^^^^^^^^^^
  File "C:\Python311\Lib\json\decoder.py", line 337, in decode
    obj, end = self.raw_decode(s, idx=_w(s, 0).end())
               ^^^^^^^^^^^^^^^^^^^^^^^^^^^^^^^^^^^^^^
  File "C:\Python311\Lib\json\decoder.py", line 355, in raw_decode
    raise JSONDecodeError("Expecting value", s, err.value) from None
json.decoder.JSONDecodeError: Expecting value: line 3 column 1 (char 4)

During handling of the above exception, another exception occurred:

Traceback (most recent call last):
  File "D:\RPA\template\Assets\Libraries\RPA\Cryptography\crypt.py", line 60, in inner
    result = f(*args, **kwargs) # Chama a função, passando seus argumentos originais (que já contém a credencial criptografada)
             ^^^^^^^^^^^^^^^^^^
  File "D:\RPA\template\Assets\Libraries\Auth\session.py", line 38, in CreateJiraInstance
    return JIRA(
           ^^^^^
  File "d:\RPA\template\venv-template\Lib\site-packages\jira\client.py", line 580, in __init__
    si = self.server_info()
         ^^^^^^^^^^^^^^^^^^
  File "d:\RPA\template\venv-template\Lib\site-packages\jira\client.py", line 3120, in server_info
    j = self._get_json("serverInfo")
        ^^^^^^^^^^^^^^^^^^^^^^^^^^^^
  File "d:\RPA\template\venv-template\Lib\site-packages\jira\client.py", line 3858, in _get_json
    raise e
  File "d:\RPA\template\venv-template\Lib\site-packages\jira\client.py", line 3855, in _get_json
    r_json = json_loads(r)
             ^^^^^^^^^^^^^
  File "d:\RPA\template\venv-template\Lib\site-packages\jira\utils\__init__.py", line 76, in json_loads
    return resp.json()
           ^^^^^^^^^^^
  File "d:\RPA\template\venv-template\Lib\site-packages\requests\models.py", line 975, in json
    raise RequestsJSONDecodeError(e.msg, e.doc, e.pos)
requests.exceptions.JSONDecodeError: Expecting value: line 3 column 1 (char 4)

During handling of the above exception, another exception occurred:

Traceback (most recent call last):
  File "D:\RPA\template\p000_main.py", line 11, in <module>
    P001_Project_Setup()
  File "D:\RPA\template\p001_project_setup.py", line 20, in __new__
    self.T02_Create_Jira_Instance()
  File "D:\RPA\template\Assets\Libraries\RPA\logger.py", line 141, in inner
    raise error
  File "D:\RPA\template\Assets\Libraries\RPA\logger.py", line 90, in inner
    f_result = f(*args, **kwargs)     # tenta executar a chamada da funçao
               ^^^^^^^^^^^^^^^^^^
  File "D:\RPA\template\p001_project_setup.py", line 41, in T02_Create_Jira_Instance
    Global.jira : JIRA = CreateJiraInstance(jira_cookies, credential = Credentials.jira)  # Cria uma nova instância do Jira
                       ^^^^^^^^^^^^^^^^^^^^^^^^^^^^^^^^^^^^^^^^^^^^^^^^^^^^^^^^^^^^^^^
  File "D:\RPA\template\Assets\Libraries\RPA\Cryptography\crypt.py", line 84, in inner
    raise Exception(f"Houve um erro na chamada da função {str(f.__qualname__.split('.')[0]).upper()}.")
Exception: Houve um erro na chamada da função CREATEJIRAINSTANCE.

During handling of the above exception, another exception occurred:

Traceback (most recent call last):
  File "D:\RPA\template\Assets\Libraries\RPA\Cryptography\crypt.py", line 60, in inner
    result = f(*args, **kwargs) # Chama a função, passando seus argumentos originais (que já contém a credencial criptografada)
             ^^^^^^^^^^^^^^^^^^
  File "D:\RPA\template\Assets\Libraries\Data\email.py", line 60, in SendEmail
    host = Global.Email['host']
           ^^^^^^^^^^^^
AttributeError: type object 'Global' has no attribute 'Email'

During handling of the above exception, another exception occurred:

Traceback (most recent call last):
  File "D:\RPA\template\Assets\Libraries\RPA\logger.py", line 90, in inner
    f_result = f(*args, **kwargs)     # tenta executar a chamada da funçao
               ^^^^^^^^^^^^^^^^^^
  File "D:\RPA\template\Events\e000_general.py", line 31, in E01_Send_Error_Report
    SendEmail(
  File "D:\RPA\template\Assets\Libraries\RPA\Cryptography\crypt.py", line 84, in inner
    raise Exception(f"Houve um erro na chamada da função {str(f.__qualname__.split('.')[0]).upper()}.")
Exception: Houve um erro na chamada da função SENDEMAIL.



Traceback (most recent call last):
  File "d:\RPA\template\venv-template\Lib\site-packages\requests\models.py", line 971, in json
    return complexjson.loads(self.text, **kwargs)
           ^^^^^^^^^^^^^^^^^^^^^^^^^^^^^^^^^^^^^^
  File "C:\Python311\Lib\json\__init__.py", line 346, in loads
    return _default_decoder.decode(s)
           ^^^^^^^^^^^^^^^^^^^^^^^^^^
  File "C:\Python311\Lib\json\decoder.py", line 337, in decode
    obj, end = self.raw_decode(s, idx=_w(s, 0).end())
               ^^^^^^^^^^^^^^^^^^^^^^^^^^^^^^^^^^^^^^
  File "C:\Python311\Lib\json\decoder.py", line 355, in raw_decode
    raise JSONDecodeError("Expecting value", s, err.value) from None
json.decoder.JSONDecodeError: Expecting value: line 3 column 1 (char 4)

During handling of the above exception, another exception occurred:

Traceback (most recent call last):
  File "D:\RPA\template\Assets\Libraries\RPA\Cryptography\crypt.py", line 60, in inner
    result = f(*args, **kwargs) # Chama a função, passando seus argumentos originais (que já contém a credencial criptografada)
             ^^^^^^^^^^^^^^^^^^
  File "D:\RPA\template\Assets\Libraries\Auth\session.py", line 38, in CreateJiraInstance
    return JIRA(
           ^^^^^
  File "d:\RPA\template\venv-template\Lib\site-packages\jira\client.py", line 580, in __init__
    si = self.server_info()
         ^^^^^^^^^^^^^^^^^^
  File "d:\RPA\template\venv-template\Lib\site-packages\jira\client.py", line 3120, in server_info
    j = self._get_json("serverInfo")
        ^^^^^^^^^^^^^^^^^^^^^^^^^^^^
  File "d:\RPA\template\venv-template\Lib\site-packages\jira\client.py", line 3858, in _get_json
    raise e
  File "d:\RPA\template\venv-template\Lib\site-packages\jira\client.py", line 3855, in _get_json
    r_json = json_loads(r)
             ^^^^^^^^^^^^^
  File "d:\RPA\template\venv-template\Lib\site-packages\jira\utils\__init__.py", line 76, in json_loads
    return resp.json()
           ^^^^^^^^^^^
  File "d:\RPA\template\venv-template\Lib\site-packages\requests\models.py", line 975, in json
    raise RequestsJSONDecodeError(e.msg, e.doc, e.pos)
requests.exceptions.JSONDecodeError: Expecting value: line 3 column 1 (char 4)

During handling of the above exception, another exception occurred:

Traceback (most recent call last):
  File "D:\RPA\template\p000_main.py", line 11, in <module>
    P001_Project_Setup()
  File "D:\RPA\template\p001_project_setup.py", line 20, in __new__
    self.T02_Create_Jira_Instance()
  File "D:\RPA\template\Assets\Libraries\RPA\logger.py", line 141, in inner
    raise error
  File "D:\RPA\template\Assets\Libraries\RPA\logger.py", line 90, in inner
    f_result = f(*args, **kwargs)     # tenta executar a chamada da funçao
               ^^^^^^^^^^^^^^^^^^
  File "D:\RPA\template\p001_project_setup.py", line 41, in T02_Create_Jira_Instance
    Global.jira : JIRA = CreateJiraInstance(jira_cookies, credential = Credentials.jira)  # Cria uma nova instância do Jira
                       ^^^^^^^^^^^^^^^^^^^^^^^^^^^^^^^^^^^^^^^^^^^^^^^^^^^^^^^^^^^^^^^
  File "D:\RPA\template\Assets\Libraries\RPA\Cryptography\crypt.py", line 84, in inner
    raise Exception(f"Houve um erro na chamada da função {str(f.__qualname__.split('.')[0]).upper()}.")
Exception: Houve um erro na chamada da função CREATEJIRAINSTANCE.
